{
 "cells": [
  {
   "cell_type": "code",
   "execution_count": 6,
   "metadata": {},
   "outputs": [
    {
     "name": "stdout",
     "output_type": "stream",
     "text": [
      "Collecting jupyterthemes\n",
      "  Downloading jupyterthemes-0.20.0-py2.py3-none-any.whl (7.0 MB)\n",
      "\u001b[K     |                                | 10 kB 3.6 kB/s eta 0:32:47\u001b[31mERROR: Exception:\n",
      "Traceback (most recent call last):\n",
      "  File \"/Applications/anaconda3/lib/python3.7/site-packages/pip/_vendor/resolvelib/resolvers.py\", line 171, in _merge_into_criterion\n",
      "    crit = self.state.criteria[name]\n",
      "KeyError: 'jupyterthemes'\n",
      "\n",
      "During handling of the above exception, another exception occurred:\n",
      "\n",
      "Traceback (most recent call last):\n",
      "  File \"/Applications/anaconda3/lib/python3.7/site-packages/pip/_vendor/urllib3/response.py\", line 438, in _error_catcher\n",
      "    yield\n",
      "  File \"/Applications/anaconda3/lib/python3.7/site-packages/pip/_vendor/urllib3/response.py\", line 519, in read\n",
      "    data = self._fp.read(amt) if not fp_closed else b\"\"\n",
      "  File \"/Applications/anaconda3/lib/python3.7/site-packages/pip/_vendor/cachecontrol/filewrapper.py\", line 62, in read\n",
      "    data = self.__fp.read(amt)\n",
      "  File \"/Applications/anaconda3/lib/python3.7/http/client.py\", line 457, in read\n",
      "    n = self.readinto(b)\n",
      "  File \"/Applications/anaconda3/lib/python3.7/http/client.py\", line 501, in readinto\n",
      "    n = self.fp.readinto(b)\n",
      "  File \"/Applications/anaconda3/lib/python3.7/socket.py\", line 589, in readinto\n",
      "    return self._sock.recv_into(b)\n",
      "  File \"/Applications/anaconda3/lib/python3.7/ssl.py\", line 1071, in recv_into\n",
      "    return self.read(nbytes, buffer)\n",
      "  File \"/Applications/anaconda3/lib/python3.7/ssl.py\", line 929, in read\n",
      "    return self._sslobj.read(len, buffer)\n",
      "socket.timeout: The read operation timed out\n",
      "\n",
      "During handling of the above exception, another exception occurred:\n",
      "\n",
      "Traceback (most recent call last):\n",
      "  File \"/Applications/anaconda3/lib/python3.7/site-packages/pip/_internal/cli/base_command.py\", line 189, in _main\n",
      "    status = self.run(options, args)\n",
      "  File \"/Applications/anaconda3/lib/python3.7/site-packages/pip/_internal/cli/req_command.py\", line 178, in wrapper\n",
      "    return func(self, options, args)\n",
      "  File \"/Applications/anaconda3/lib/python3.7/site-packages/pip/_internal/commands/install.py\", line 317, in run\n",
      "    reqs, check_supported_wheels=not options.target_dir\n",
      "  File \"/Applications/anaconda3/lib/python3.7/site-packages/pip/_internal/resolution/resolvelib/resolver.py\", line 122, in resolve\n",
      "    requirements, max_rounds=try_to_avoid_resolution_too_deep,\n",
      "  File \"/Applications/anaconda3/lib/python3.7/site-packages/pip/_vendor/resolvelib/resolvers.py\", line 453, in resolve\n",
      "    state = resolution.resolve(requirements, max_rounds=max_rounds)\n",
      "  File \"/Applications/anaconda3/lib/python3.7/site-packages/pip/_vendor/resolvelib/resolvers.py\", line 318, in resolve\n",
      "    name, crit = self._merge_into_criterion(r, parent=None)\n",
      "  File \"/Applications/anaconda3/lib/python3.7/site-packages/pip/_vendor/resolvelib/resolvers.py\", line 173, in _merge_into_criterion\n",
      "    crit = Criterion.from_requirement(self._p, requirement, parent)\n",
      "  File \"/Applications/anaconda3/lib/python3.7/site-packages/pip/_vendor/resolvelib/resolvers.py\", line 82, in from_requirement\n",
      "    if not cands:\n",
      "  File \"/Applications/anaconda3/lib/python3.7/site-packages/pip/_vendor/resolvelib/structs.py\", line 124, in __bool__\n",
      "    return bool(self._sequence)\n",
      "  File \"/Applications/anaconda3/lib/python3.7/site-packages/pip/_internal/resolution/resolvelib/found_candidates.py\", line 143, in __bool__\n",
      "    return any(self)\n",
      "  File \"/Applications/anaconda3/lib/python3.7/site-packages/pip/_internal/resolution/resolvelib/found_candidates.py\", line 38, in _iter_built\n",
      "    candidate = func()\n",
      "  File \"/Applications/anaconda3/lib/python3.7/site-packages/pip/_internal/resolution/resolvelib/factory.py\", line 169, in _make_candidate_from_link\n",
      "    name=name, version=version,\n",
      "  File \"/Applications/anaconda3/lib/python3.7/site-packages/pip/_internal/resolution/resolvelib/candidates.py\", line 306, in __init__\n",
      "    version=version,\n",
      "  File \"/Applications/anaconda3/lib/python3.7/site-packages/pip/_internal/resolution/resolvelib/candidates.py\", line 144, in __init__\n",
      "    self.dist = self._prepare()\n",
      "  File \"/Applications/anaconda3/lib/python3.7/site-packages/pip/_internal/resolution/resolvelib/candidates.py\", line 226, in _prepare\n",
      "    dist = self._prepare_distribution()\n",
      "  File \"/Applications/anaconda3/lib/python3.7/site-packages/pip/_internal/resolution/resolvelib/candidates.py\", line 312, in _prepare_distribution\n",
      "    self._ireq, parallel_builds=True,\n",
      "  File \"/Applications/anaconda3/lib/python3.7/site-packages/pip/_internal/operations/prepare.py\", line 457, in prepare_linked_requirement\n",
      "    return self._prepare_linked_requirement(req, parallel_builds)\n",
      "  File \"/Applications/anaconda3/lib/python3.7/site-packages/pip/_internal/operations/prepare.py\", line 482, in _prepare_linked_requirement\n",
      "    self.download_dir, hashes,\n",
      "  File \"/Applications/anaconda3/lib/python3.7/site-packages/pip/_internal/operations/prepare.py\", line 234, in unpack_url\n",
      "    hashes=hashes,\n",
      "  File \"/Applications/anaconda3/lib/python3.7/site-packages/pip/_internal/operations/prepare.py\", line 108, in get_http_url\n",
      "    from_path, content_type = download(link, temp_dir.path)\n",
      "  File \"/Applications/anaconda3/lib/python3.7/site-packages/pip/_internal/network/download.py\", line 163, in __call__\n",
      "    for chunk in chunks:\n",
      "  File \"/Applications/anaconda3/lib/python3.7/site-packages/pip/_internal/cli/progress_bars.py\", line 159, in iter\n",
      "    for x in it:\n",
      "  File \"/Applications/anaconda3/lib/python3.7/site-packages/pip/_internal/network/utils.py\", line 88, in response_chunks\n",
      "    decode_content=False,\n",
      "  File \"/Applications/anaconda3/lib/python3.7/site-packages/pip/_vendor/urllib3/response.py\", line 576, in stream\n",
      "    data = self.read(amt=amt, decode_content=decode_content)\n",
      "  File \"/Applications/anaconda3/lib/python3.7/site-packages/pip/_vendor/urllib3/response.py\", line 541, in read\n",
      "    raise IncompleteRead(self._fp_bytes_read, self.length_remaining)\n",
      "  File \"/Applications/anaconda3/lib/python3.7/contextlib.py\", line 130, in __exit__\n",
      "    self.gen.throw(type, value, traceback)\n",
      "  File \"/Applications/anaconda3/lib/python3.7/site-packages/pip/_vendor/urllib3/response.py\", line 443, in _error_catcher\n",
      "    raise ReadTimeoutError(self._pool, None, \"Read timed out.\")\n",
      "pip._vendor.urllib3.exceptions.ReadTimeoutError: HTTPSConnectionPool(host='files.pythonhosted.org', port=443): Read timed out.\u001b[0m\n",
      "Note: you may need to restart the kernel to use updated packages.\n"
     ]
    }
   ],
   "source": [
    "pip install jupyterthemes"
   ]
  },
  {
   "cell_type": "code",
   "execution_count": 5,
   "metadata": {},
   "outputs": [
    {
     "name": "stdout",
     "output_type": "stream",
     "text": [
      "Collecting jupyterthemes\n",
      "  Downloading jupyterthemes-0.20.0-py2.py3-none-any.whl (7.0 MB)\n",
      "\u001b[K     |█▌                              | 337 kB 3.3 kB/s eta 0:33:57\u001b[31mERROR: Exception:\n",
      "Traceback (most recent call last):\n",
      "  File \"/Applications/anaconda3/lib/python3.7/site-packages/pip/_vendor/resolvelib/resolvers.py\", line 171, in _merge_into_criterion\n",
      "    crit = self.state.criteria[name]\n",
      "KeyError: 'jupyterthemes'\n",
      "\n",
      "During handling of the above exception, another exception occurred:\n",
      "\n",
      "Traceback (most recent call last):\n",
      "  File \"/Applications/anaconda3/lib/python3.7/site-packages/pip/_vendor/urllib3/response.py\", line 438, in _error_catcher\n",
      "    yield\n",
      "  File \"/Applications/anaconda3/lib/python3.7/site-packages/pip/_vendor/urllib3/response.py\", line 519, in read\n",
      "    data = self._fp.read(amt) if not fp_closed else b\"\"\n",
      "  File \"/Applications/anaconda3/lib/python3.7/site-packages/pip/_vendor/cachecontrol/filewrapper.py\", line 62, in read\n",
      "    data = self.__fp.read(amt)\n",
      "  File \"/Applications/anaconda3/lib/python3.7/http/client.py\", line 457, in read\n",
      "    n = self.readinto(b)\n",
      "  File \"/Applications/anaconda3/lib/python3.7/http/client.py\", line 501, in readinto\n",
      "    n = self.fp.readinto(b)\n",
      "  File \"/Applications/anaconda3/lib/python3.7/socket.py\", line 589, in readinto\n",
      "    return self._sock.recv_into(b)\n",
      "  File \"/Applications/anaconda3/lib/python3.7/ssl.py\", line 1071, in recv_into\n",
      "    return self.read(nbytes, buffer)\n",
      "  File \"/Applications/anaconda3/lib/python3.7/ssl.py\", line 929, in read\n",
      "    return self._sslobj.read(len, buffer)\n",
      "socket.timeout: The read operation timed out\n",
      "\n",
      "During handling of the above exception, another exception occurred:\n",
      "\n",
      "Traceback (most recent call last):\n",
      "  File \"/Applications/anaconda3/lib/python3.7/site-packages/pip/_internal/cli/base_command.py\", line 189, in _main\n",
      "    status = self.run(options, args)\n",
      "  File \"/Applications/anaconda3/lib/python3.7/site-packages/pip/_internal/cli/req_command.py\", line 178, in wrapper\n",
      "    return func(self, options, args)\n",
      "  File \"/Applications/anaconda3/lib/python3.7/site-packages/pip/_internal/commands/install.py\", line 317, in run\n",
      "    reqs, check_supported_wheels=not options.target_dir\n",
      "  File \"/Applications/anaconda3/lib/python3.7/site-packages/pip/_internal/resolution/resolvelib/resolver.py\", line 122, in resolve\n",
      "    requirements, max_rounds=try_to_avoid_resolution_too_deep,\n",
      "  File \"/Applications/anaconda3/lib/python3.7/site-packages/pip/_vendor/resolvelib/resolvers.py\", line 453, in resolve\n",
      "    state = resolution.resolve(requirements, max_rounds=max_rounds)\n",
      "  File \"/Applications/anaconda3/lib/python3.7/site-packages/pip/_vendor/resolvelib/resolvers.py\", line 318, in resolve\n",
      "    name, crit = self._merge_into_criterion(r, parent=None)\n",
      "  File \"/Applications/anaconda3/lib/python3.7/site-packages/pip/_vendor/resolvelib/resolvers.py\", line 173, in _merge_into_criterion\n",
      "    crit = Criterion.from_requirement(self._p, requirement, parent)\n",
      "  File \"/Applications/anaconda3/lib/python3.7/site-packages/pip/_vendor/resolvelib/resolvers.py\", line 82, in from_requirement\n",
      "    if not cands:\n",
      "  File \"/Applications/anaconda3/lib/python3.7/site-packages/pip/_vendor/resolvelib/structs.py\", line 124, in __bool__\n",
      "    return bool(self._sequence)\n",
      "  File \"/Applications/anaconda3/lib/python3.7/site-packages/pip/_internal/resolution/resolvelib/found_candidates.py\", line 143, in __bool__\n",
      "    return any(self)\n",
      "  File \"/Applications/anaconda3/lib/python3.7/site-packages/pip/_internal/resolution/resolvelib/found_candidates.py\", line 38, in _iter_built\n",
      "    candidate = func()\n",
      "  File \"/Applications/anaconda3/lib/python3.7/site-packages/pip/_internal/resolution/resolvelib/factory.py\", line 169, in _make_candidate_from_link\n",
      "    name=name, version=version,\n",
      "  File \"/Applications/anaconda3/lib/python3.7/site-packages/pip/_internal/resolution/resolvelib/candidates.py\", line 306, in __init__\n",
      "    version=version,\n",
      "  File \"/Applications/anaconda3/lib/python3.7/site-packages/pip/_internal/resolution/resolvelib/candidates.py\", line 144, in __init__\n",
      "    self.dist = self._prepare()\n",
      "  File \"/Applications/anaconda3/lib/python3.7/site-packages/pip/_internal/resolution/resolvelib/candidates.py\", line 226, in _prepare\n",
      "    dist = self._prepare_distribution()\n",
      "  File \"/Applications/anaconda3/lib/python3.7/site-packages/pip/_internal/resolution/resolvelib/candidates.py\", line 312, in _prepare_distribution\n",
      "    self._ireq, parallel_builds=True,\n",
      "  File \"/Applications/anaconda3/lib/python3.7/site-packages/pip/_internal/operations/prepare.py\", line 457, in prepare_linked_requirement\n",
      "    return self._prepare_linked_requirement(req, parallel_builds)\n",
      "  File \"/Applications/anaconda3/lib/python3.7/site-packages/pip/_internal/operations/prepare.py\", line 482, in _prepare_linked_requirement\n",
      "    self.download_dir, hashes,\n",
      "  File \"/Applications/anaconda3/lib/python3.7/site-packages/pip/_internal/operations/prepare.py\", line 234, in unpack_url\n",
      "    hashes=hashes,\n",
      "  File \"/Applications/anaconda3/lib/python3.7/site-packages/pip/_internal/operations/prepare.py\", line 108, in get_http_url\n",
      "    from_path, content_type = download(link, temp_dir.path)\n",
      "  File \"/Applications/anaconda3/lib/python3.7/site-packages/pip/_internal/network/download.py\", line 163, in __call__\n",
      "    for chunk in chunks:\n",
      "  File \"/Applications/anaconda3/lib/python3.7/site-packages/pip/_internal/cli/progress_bars.py\", line 159, in iter\n",
      "    for x in it:\n",
      "  File \"/Applications/anaconda3/lib/python3.7/site-packages/pip/_internal/network/utils.py\", line 88, in response_chunks\n",
      "    decode_content=False,\n",
      "  File \"/Applications/anaconda3/lib/python3.7/site-packages/pip/_vendor/urllib3/response.py\", line 576, in stream\n",
      "    data = self.read(amt=amt, decode_content=decode_content)\n",
      "  File \"/Applications/anaconda3/lib/python3.7/site-packages/pip/_vendor/urllib3/response.py\", line 541, in read\n",
      "    raise IncompleteRead(self._fp_bytes_read, self.length_remaining)\n",
      "  File \"/Applications/anaconda3/lib/python3.7/contextlib.py\", line 130, in __exit__\n",
      "    self.gen.throw(type, value, traceback)\n",
      "  File \"/Applications/anaconda3/lib/python3.7/site-packages/pip/_vendor/urllib3/response.py\", line 443, in _error_catcher\n",
      "    raise ReadTimeoutError(self._pool, None, \"Read timed out.\")\n",
      "pip._vendor.urllib3.exceptions.ReadTimeoutError: HTTPSConnectionPool(host='files.pythonhosted.org', port=443): Read timed out.\u001b[0m\n",
      "Note: you may need to restart the kernel to use updated packages.\n"
     ]
    }
   ],
   "source": [
    "pip install --upgrade jupyterthemes"
   ]
  },
  {
   "cell_type": "code",
   "execution_count": null,
   "metadata": {},
   "outputs": [],
   "source": []
  }
 ],
 "metadata": {
  "kernelspec": {
   "display_name": "Python 3",
   "language": "python",
   "name": "python3"
  },
  "language_info": {
   "codemirror_mode": {
    "name": "ipython",
    "version": 3
   },
   "file_extension": ".py",
   "mimetype": "text/x-python",
   "name": "python",
   "nbconvert_exporter": "python",
   "pygments_lexer": "ipython3",
   "version": "3.7.4"
  }
 },
 "nbformat": 4,
 "nbformat_minor": 2
}
